Workbook

Sheet 說明
A1: MyFactory 實際貨批模擬 — 填寫範本
A2: 填好這份檔案後載入模擬器，就會用你真實的 WIP 跑各種排程法則，比較「這批貨全部做完要多久」。
A4: 怎麼填
A5: 「貨批」分頁 | C5: 一列一批待測貨。把現場 WIP 清單貼進來，必填欄位不能空白。
A6: 「機台」分頁 | C6: 一列一台測試機，包含它現在裝著什麼 Kit、載著什麼程式。
A7: 藍色字的範例列 | C7: 第 2 列起的藍色字是範例，照格式填好自己的資料後把它們刪掉。
A8: 「能力矩陣」分頁 | C8: 機台 × 封裝的打勾表。有這頁就以它為準，蓋過「機台」分頁的 can_packages；刪掉整頁就回去讀 can_packages。
A9: 欄位標題 | C9: 滑鼠移到標題格會跳出這個欄位的中文說明。
A10: 代號自由命名 | C10: package / program 直接用你現場的名字，種類多少都可以，模擬器會自動吃進去。
A12: 貨批 — 欄位說明
A13: 欄位 | B13: 必填 | C13: 說明 | D13: 範例
A14: lot_id | B14: 必填 | C14: 批號，不可重複。直接用現場批號。 | D14: LOT-0001
A15: package | B15: 必填 | C15: 封裝／Kit 代號。同代號＝同一套 Kit，換到不同代號才要換 Kit（60 分）。 | D15: QFN48
A16: program | B16: 必填 | C16: 測試程式名稱或版本。package 相同但 program 不同＝只換程式（30 分）。 | D16: MCU01_V3
A17: qty | B17: 必填 | C17: 這批的顆數。 | D17: 8000
A18: tpu_sec | B18: 必填 | C18: 單一 site 測一顆要幾秒。不是整批時間，也不是多 site 的等效時間。 | D18: 2.1
A19: arrive_h | B19: 選填 | C19: 到廠時間，以「現在」為 0 的小時數。空白＝已經在 WIP 裡等著。 | D19: 0
A20: due_h | B20: 選填 | C20: 交期，同樣以現在為 0 的小時數。空白＝這批不看交期。 | D20: 36
A21: hot | B21: 選填 | C21: Y＝急件（可插單）。空白或 N＝一般批。 | D21: N
A22: yield_pct | B22: 選填 | C22: 這個料號的實際良率百分比。空白＝用參數設定的隨機區間。 | D22: 96.5
A23: note | B23: 選填 | C23: 備註，不影響模擬結果。 | D23: 主力機種
A25: 機台 — 欄位說明
A26: 欄位 | B26: 必填 | C26: 說明 | D26: 範例
A27: machine_id | B27: 必填 | C27: 機台名稱。 | D27: T01
A28: sites | B28: 必填 | C28: site 數，直接當速度倍率。8 site 的機台填 8，同一批只要 1 site 的 1/8 時間。 | D28: 8
A29: kit_now | B29: 選填 | C29: 現在機台上裝著的 Kit，填 package 代號。空白＝空機，第一批要先換 Kit。 | D29: QFN48
A30: prog_now | B30: 選填 | C30: 現在載入的測試程式。空白＝沒有程式，第一批要載入。 | D30: MCU01_V3
A31: can_packages | B31: 選填 | C31: 這台能測哪些封裝，用直線 | 分隔。空白＝全部都能測。 | D31: QFN48|QFN32
A32: available_at_h | B32: 選填 | C32: 幾小時後才空出來（正在跑別的貨、保養中）。空白＝現在就能用。 | D32: 0
A34: 填完自動檢查（不用手動算，改資料會跟著變）
A35: 項目 | C35: 數值 | D35: 單位
A36: 貨批筆數 | C36: =COUNTA(貨批!A2:A5000) | D36: 筆
A37: 總顆數 | C37: =SUM(貨批!D2:D5000) | D37: 顆
A38: 純測試工時（1 site） | C38: =SUMPRODUCT(貨批!D2:D5000,貨批!E2:E5000)/3600 | D38: 小時
A39: 機台台數 | C39: =COUNTA(機台!A2:A500) | D39: 台
A40: 機隊等效 site 總數 | C40: =SUM(機台!B2:B500) | D40: site
A41: 理論最短清空時間 | C41: =IFERROR(C38/C40,0) | D41: 小時（不含改機與當機，排程再好也快不過這個）
A43: 「理論最短清空時間」＝ 純測試工時 ÷ 機隊等效 site 總數。它假設零改機、零當機、機台永遠不閒著，
A44: 所以實際一定比它長。模擬跑出來的數字離它多遠，就是改機與排程吃掉的部分。

Sheet 貨批
A1: lot_id | B1: package | C1: program | D1: qty | E1: tpu_sec | F1: arrive_h | G1: due_h | H1: hot | I1: yield_pct | J1: note
A2: LOT-0001 | B2: QFN32 | C2: PMIC07_V2 | D2: 5500 | E2: 3.25 | F2: 0 | G2: 20.4 | H2: N | I2: 93.1 | J2: 中批
A3: LOT-0002 | B3: QFN48 | C3: MCU01_V3 | D3: 700 | E3: 2.2 | F3: 0 | G3: 9.7 | H3: N | J3: 小批
A4: LOT-0003 | B4: SOP16 | C4: LED03_V1 | D4: 7500 | E4: 1.17 | F4: 0 | G4: 16.5 | H4: N | J4: 中批
A5: LOT-0004 | B5: SOP16 | C5: LED03_V1 | D5: 1400 | E5: 1.24 | F5: 0 | G5: 6.8 | H5: N | J5: 小批
A6: LOT-0005 | B6: SOP16 | C6: LED03_V1 | D6: 21000 | E6: 1.19 | F6: 0 | G6: 14.4 | H6: N | I6: 98.8 | J6: 大批
A7: LOT-0006 | B7: QFN32 | C7: PMIC07_V2 | D7: 600 | E7: 3.2 | F7: 0 | G7: 10.3 | H7: N | J7: 小批
A8: LOT-0007 | B8: QFN32 | C8: PMIC07_V2 | D8: 600 | E8: 3.38 | F8: 0 | G8: 5.4 | H8: N | I8: 92.3 | J8: 小批
A9: LOT-0008 | B9: QFN32 | C9: PMIC07_V2 | D9: 1200 | E9: 3.46 | F9: 0 | G9: 12.1 | H9: N | I9: 90.3 | J9: 小批
A10: LOT-0009 | B10: QFN32 | C10: PMIC07_V2 | D10: 13000 | E10: 3.66 | F10: 0 | G10: 30.8 | H10: N | J10: 大批
A11: LOT-0010 | B11: QFN32 | C11: PMIC07_V2 | D11: 1800 | E11: 3.22 | F11: 0 | G11: 8 | H11: N | I11: 90.8 | J11: 小批
A12: LOT-0011 | B12: QFN32 | C12: PMIC07_V2 | D12: 6500 | E12: 3.28 | F12: 0 | G12: 20.8 | H12: N | I12: 92.5 | J12: 中批
A13: LOT-0012 | B13: QFN48 | C13: MCU01_V3 | D13: 1400 | E13: 1.99 | F13: 0 | G13: 5.4 | H13: N | J13: 小批
A14: LOT-0013 | B14: QFN48 | C14: MCU01_V5 | D14: 900 | E14: 2.26 | F14: 0 | G14: 12.3 | H14: N | I14: 94.8 | J14: 小批
A15: LOT-0014 | B15: QFN48 | C15: MCU01_V3 | D15: 7500 | E15: 2.04 | F15: 0 | G15: 11 | H15: N | J15: 中批
A16: LOT-0015 | B16: QFN48 | C16: MCU01_V3 | D16: 800 | E16: 2.08 | F16: 0 | G16: 11.4 | H16: N | I16: 97.7 | J16: 小批
A17: LOT-0016 | B17: SOP16 | C17: LED03_V1 | D17: 1800 | E17: 1.13 | F17: 0 | G17: 2.8 | H17: Y | J17: 小批・急件
A18: LOT-0017 | B18: QFN48 | C18: MCU01_V5 | D18: 600 | E18: 2.26 | F18: 0 | G18: 10 | H18: N | J18: 小批
A19: LOT-0018 | B19: QFN48 | C19: MCU01_V5 | D19: 1300 | E19: 2.12 | F19: 0 | G19: 8.9 | H19: N | I19: 95 | J19: 小批
A20: LOT-0019 | B20: QFN48 | C20: MCU01_V3 | D20: 1300 | E20: 1.99 | F20: 0 | G20: 10.6 | H20: N | I20: 95.3 | J20: 小批
A21: LOT-0020 | B21: QFN48 | C21: MCU01_V3 | D21: 700 | E21: 1.98 | F21: 0 | G21: 8.2 | H21: N | I21: 96.1 | J21: 小批
A22: LOT-0021 | B22: QFN32 | C22: PMIC07_V2 | D22: 900 | E22: 3.63 | F22: 0 | G22: 13.1 | H22: N | J22: 小批
A23: LOT-0022 | B23: QFN32 | C23: PMIC07_V2 | D23: 2500 | E23: 3.53 | F23: 0 | G23: 15.3 | H23: N | I23: 92.8 | J23: 中批
A24: LOT-0023 | B24: QFN32 | C24: PMIC07_V2 | D24: 800 | E24: 3.28 | F24: 0 | G24: 3.2 | H24: Y | I24: 91.6 | J24: 小批・急件
A25: LOT-0024 | B25: QFN32 | C25: PMIC07_V2 | D25: 1900 | E25: 3.34 | F25: 0 | G25: 11.4 | H25: N | J25: 小批
A26: LOT-0025 | B26: QFN32 | C26: PMIC07_V2 | D26: 1800 | E26: 3.39 | F26: 0 | G26: 10.4 | H26: N | J26: 小批
A27: LOT-0026 | B27: QFN48 | C27: MCU01_V3 | D27: 5500 | E27: 2.25 | F27: 0 | G27: 15.7 | H27: N | I27: 95.8 | J27: 中批
A28: LOT-0027 | B28: QFN48 | C28: MCU01_V3 | D28: 1100 | E28: 1.96 | F28: 0 | G28: 3.8 | H28: Y | I28: 97 | J28: 小批・急件
A29: LOT-0028 | B29: SOP16 | C29: LED03_V1 | D29: 24000 | E29: 1.23 | F29: 0 | G29: 25 | H29: N | I29: 97.3 | J29: 大批
A30: LOT-0029 | B30: QFN48 | C30: MCU01_V5 | D30: 6500 | E30: 2.18 | F30: 0 | G30: 10.7 | H30: N | J30: 中批
A31: LOT-0030 | B31: QFN48 | C31: MCU01_V5 | D31: 600 | E31: 1.97 | F31: 0 | G31: 12.6 | H31: N | I31: 92.8 | J31: 小批
A32: LOT-0031 | B32: QFN48 | C32: MCU01_V5 | D32: 5000 | E32: 2.25 | F32: 0 | G32: 10.2 | H32: N | J32: 中批
A33: LOT-0032 | B33: QFN48 | C33: MCU01_V5 | D33: 1300 | E33: 2.17 | F33: 0 | G33: 10.8 | H33: N | I33: 94.7 | J33: 小批
A34: LOT-0033 | B34: TSSOP28 | C34: SENS11_V4 | D34: 800 | E34: 2.63 | F34: 0 | G34: 11.1 | H34: N | J34: 小批
A35: LOT-0034 | B35: TSSOP28 | C35: SENS11_V4 | D35: 1800 | E35: 2.98 | F35: 0 | G35: 8.2 | H35: N | J35: 小批
A36: LOT-0035 | B36: TSSOP28 | C36: SENS11_V4 | D36: 21000 | E36: 2.93 | F36: 0 | G36: 18.7 | H36: N | I36: 90.2 | J36: 大批
A37: LOT-0036 | B37: QFN48 | C37: MCU01_V3 | D37: 6500 | E37: 2.07 | F37: 0 | G37: 3.5 | H37: Y | J37: 中批・急件
A38: LOT-0037 | B38: QFN48 | C38: MCU01_V3 | D38: 1600 | E38: 2.09 | F38: 0 | G38: 13 | H38: N | J38: 小批
A39: LOT-0038 | B39: QFN48 | C39: MCU01_V3 | D39: 12500 | E39: 2.19 | F39: 0 | G39: 20.7 | H39: N | J39: 大批
A40: LOT-0039 | B40: SOP16 | C40: LED03_V1 | D40: 1600 | E40: 1.12 | F40: 0 | G40: 5.4 | H40: N | J40: 小批
...

Sheet 機台
A1: machine_id | B1: sites | C1: kit_now | D1: prog_now | E1: can_packages | F1: available_at_h
A2: T01 | B2: 8 | C2: QFN48 | D2: MCU01_V3 | E2: QFN48|QFN32 | F2: 0
A3: T02 | B3: 8 | C3: QFN48 | D3: MCU01_V5 | E3: QFN48|QFN32 | F3: 0
A4: T03 | B4: 4 | C4: QFN32 | D4: PMIC07_V2 | F4: 0
A5: T04 | B5: 4 | E5: SOP16|TSSOP28 | F5: 0
A6: T05 | B6: 2 | C6: SOP16 | D6: LED03_V1 | E6: SOP16 | F6: 4

Sheet 能力矩陣
A1: 機台 | B1: sites | C1: QFN32 | D1: QFN48 | E1: SOP16 | F1: TSSOP28 | G1: 目前裝著的 Kit | H1: 目前程式 | I1: 幾小時後可用
A2: T01 | B2: 8 | C2: ✔ | D2: ✔ | G2: QFN48 | H2: MCU01_V3 | I2: 0
A3: T02 | B3: 8 | C3: ✔ | D3: ✔ | G3: QFN48 | H3: MCU01_V5 | I3: 0
A4: T03 | B4: 4 | C4: ✔ | D4: ✔ | E4: ✔ | F4: ✔ | G4: QFN32 | H4: PMIC07_V2 | I4: 0
A5: T04 | B5: 4 | E5: ✔ | F5: ✔ | I5: 0
A6: T05 | B6: 2 | E6: ✔ | G6: SOP16 | H6: LED03_V1 | I6: 4
A8: 能測這種封裝的機台數 | C8: =COUNTIF(C2:C6,"✔") | D8: =COUNTIF(D2:D6,"✔") | E8: =COUNTIF(E2:E6,"✔") | F8: =COUNTIF(F2:F6,"✔")
A9: 能測這種封裝的 site 合計 | C9: =SUMIF(C2:C6,"✔",$B$2:$B$6) | D9: =SUMIF(D2:D6,"✔",$B$2:$B$6) | E9: =SUMIF(E2:E6,"✔",$B$2:$B$6) | F9: =SUMIF(F2:F6,"✔",$B$2:$B$6)
A10: 目前正裝著這種 Kit 的 site | C10: =SUMIF($G$2:$G$6,C$1,$B$2:$B$6) | D10: =SUMIF($G$2:$G$6,D$1,$B$2:$B$6) | E10: =SUMIF($G$2:$G$6,E$1,$B$2:$B$6) | F10: =SUMIF($G$2:$G$6,F$1,$B$2:$B$6)
A11: 這批貨的工時（分，1 site） | C11: =SUMPRODUCT((貨批!$B$2:$B$5000=C$1)*貨批!$D$2:$D$5000*貨批!$E$2:$E$5000)/60 | D11: =SUMPRODUCT((貨批!$B$2:$B$5000=D$1)*貨批!$D$2:$D$5000*貨批!$E$2:$E$5000)/60 | E11: =SUMPRODUCT((貨批!$B$2:$B$5000=E$1)*貨批!$D$2:$D$5000*貨批!$E$2:$E$5000)/60 | F11: =SUMPRODUCT((貨批!$B$2:$B$5000=F$1)*貨批!$D$2:$D$5000*貨批!$E$2:$E$5000)/60
A12: 若完全不換 Kit，要跑幾小時 | C12: =IFERROR(C11/C10/60,"—") | D12: =IFERROR(D11/D10/60,"—") | E12: =IFERROR(E11/E10/60,"—") | F12: =IFERROR(F11/F10/60,"—")
A14: ✔ ＝ 這台機可以測這種封裝。要改就直接在格子裡打勾或清掉，模擬器以這頁為準。
A15: （打勾符號用 ✔ V O Y 1 都可以；留白或填 X 就是不能測。整列都沒勾＝視為全部都能測。）
A16: 黃底 ＝ 這台機「現在」裝著的 Kit，也就是機隊此刻停在什麼配置。
A17: 最後一列是重點：把機隊凍結在現在的配置（完全不換 Kit），每種封裝各要跑多久。
A18: 哪一種明顯偏高，就是這批貨的瓶頸——代表它的量和現在裝著它的 site 數對不上，得先換 Kit 把配置拉回來。
A19: 刪掉整頁也可以，模擬器會改用「機台」分頁的 can_packages。
A20: 機台清單（台數、sites、目前 Kit、幾小時後可用）仍然以「機台」分頁為準，這頁只決定能力。
A21: 要加機台：在現有的列中間「插入列」，下面的統計公式會自己跟著長；直接往最後一列底下打字則不會。

Sheet 配件
A1: package | B1: kits
A2: QFN32 | B2: 2
A3: QFN48 | B3: 2
A4: SOP16 | B4: 2
A5: TSSOP28 | B5: 1
A7: 每種封裝有幾套 Kit 治具 —— 同一時間最多只有這麼多台機能裝著它。
A8: 留白 ＝ 這種封裝的治具不限量；整頁刪掉 ＝ 全部都不限量（跟舊版行為一樣）。
A9: 機台想換到某個 Kit，但該封裝的治具都在別台機上時，它會停下來等，
A10: 時間軸上會顯示為「等 Kit」（灰色），跑分表也會多一欄「等 Kit 分鐘」。
A11: 閒置且待接區沒有同封裝批的機台，身上的治具會被搬走給需要的機台（比照現場實務）。
A12: 開局時如果裝著某封裝的機台數超過套數，多出來的會被當成空機。
